2023-05-08 21:07:09,788 INFO: Starting Songversation... [in /Users/GihadCoorey11/Desktop/CITS3403/Songversation/app/__init__.py:42]
2023-05-08 21:08:15,062 ERROR: Exception on /get-track-lyrics [GET] [in /Users/GihadCoorey11/Desktop/CITS3403/Songversation/Songversation-venv/lib/python3.11/site-packages/flask/app.py:1744]
Traceback (most recent call last):
  File "/Users/GihadCoorey11/Desktop/CITS3403/Songversation/Songversation-venv/lib/python3.11/site-packages/sqlalchemy/engine/base.py", line 1964, in _exec_single_context
    self.dialect.do_execute(
  File "/Users/GihadCoorey11/Desktop/CITS3403/Songversation/Songversation-venv/lib/python3.11/site-packages/sqlalchemy/engine/default.py", line 748, in do_execute
    cursor.execute(statement, parameters)
sqlite3.OperationalError: no such table: track_lyrics

The above exception was the direct cause of the following exception:

Traceback (most recent call last):
  File "/Users/GihadCoorey11/Desktop/CITS3403/Songversation/Songversation-venv/lib/python3.11/site-packages/flask/app.py", line 2528, in wsgi_app
    response = self.full_dispatch_request()
               ^^^^^^^^^^^^^^^^^^^^^^^^^^^^
  File "/Users/GihadCoorey11/Desktop/CITS3403/Songversation/Songversation-venv/lib/python3.11/site-packages/flask/app.py", line 1825, in full_dispatch_request
    rv = self.handle_user_exception(e)
         ^^^^^^^^^^^^^^^^^^^^^^^^^^^^^
  File "/Users/GihadCoorey11/Desktop/CITS3403/Songversation/Songversation-venv/lib/python3.11/site-packages/flask/app.py", line 1823, in full_dispatch_request
    rv = self.dispatch_request()
         ^^^^^^^^^^^^^^^^^^^^^^^
  File "/Users/GihadCoorey11/Desktop/CITS3403/Songversation/Songversation-venv/lib/python3.11/site-packages/flask/app.py", line 1799, in dispatch_request
    return self.ensure_sync(self.view_functions[rule.endpoint])(**view_args)
           ^^^^^^^^^^^^^^^^^^^^^^^^^^^^^^^^^^^^^^^^^^^^^^^^^^^^^^^^^^^^^^^^^
  File "/Users/GihadCoorey11/Desktop/CITS3403/Songversation/Songversation-venv/lib/python3.11/site-packages/asgiref/sync.py", line 240, in __call__
    return call_result.result()
           ^^^^^^^^^^^^^^^^^^^^
  File "/opt/homebrew/Cellar/python@3.11/3.11.3/Frameworks/Python.framework/Versions/3.11/lib/python3.11/concurrent/futures/_base.py", line 449, in result
    return self.__get_result()
           ^^^^^^^^^^^^^^^^^^^
  File "/opt/homebrew/Cellar/python@3.11/3.11.3/Frameworks/Python.framework/Versions/3.11/lib/python3.11/concurrent/futures/_base.py", line 401, in __get_result
    raise self._exception
  File "/Users/GihadCoorey11/Desktop/CITS3403/Songversation/Songversation-venv/lib/python3.11/site-packages/asgiref/sync.py", line 306, in main_wrap
    result = await self.awaitable(*args, **kwargs)
             ^^^^^^^^^^^^^^^^^^^^^^^^^^^^^^^^^^^^^
  File "/Users/GihadCoorey11/Desktop/CITS3403/Songversation/app/api/spotify_api.py", line 140, in get_track_lyrics
    lyric_cache = TrackLyrics.query.filter(TrackLyrics.track_id == track_id).first()
                  ^^^^^^^^^^^^^^^^^^^^^^^^^^^^^^^^^^^^^^^^^^^^^^^^^^^^^^^^^^^^^^^^^^
  File "/Users/GihadCoorey11/Desktop/CITS3403/Songversation/Songversation-venv/lib/python3.11/site-packages/sqlalchemy/orm/query.py", line 2752, in first
    return self.limit(1)._iter().first()  # type: ignore
           ^^^^^^^^^^^^^^^^^^^^^
  File "/Users/GihadCoorey11/Desktop/CITS3403/Songversation/Songversation-venv/lib/python3.11/site-packages/sqlalchemy/orm/query.py", line 2855, in _iter
    result: Union[ScalarResult[_T], Result[_T]] = self.session.execute(
                                                  ^^^^^^^^^^^^^^^^^^^^^
  File "/Users/GihadCoorey11/Desktop/CITS3403/Songversation/Songversation-venv/lib/python3.11/site-packages/sqlalchemy/orm/session.py", line 2229, in execute
    return self._execute_internal(
           ^^^^^^^^^^^^^^^^^^^^^^^
  File "/Users/GihadCoorey11/Desktop/CITS3403/Songversation/Songversation-venv/lib/python3.11/site-packages/sqlalchemy/orm/session.py", line 2124, in _execute_internal
    result: Result[Any] = compile_state_cls.orm_execute_statement(
                          ^^^^^^^^^^^^^^^^^^^^^^^^^^^^^^^^^^^^^^^^
  File "/Users/GihadCoorey11/Desktop/CITS3403/Songversation/Songversation-venv/lib/python3.11/site-packages/sqlalchemy/orm/context.py", line 253, in orm_execute_statement
    result = conn.execute(
             ^^^^^^^^^^^^^
  File "/Users/GihadCoorey11/Desktop/CITS3403/Songversation/Songversation-venv/lib/python3.11/site-packages/sqlalchemy/engine/base.py", line 1414, in execute
    return meth(
           ^^^^^
  File "/Users/GihadCoorey11/Desktop/CITS3403/Songversation/Songversation-venv/lib/python3.11/site-packages/sqlalchemy/sql/elements.py", line 486, in _execute_on_connection
    return connection._execute_clauseelement(
           ^^^^^^^^^^^^^^^^^^^^^^^^^^^^^^^^^^
  File "/Users/GihadCoorey11/Desktop/CITS3403/Songversation/Songversation-venv/lib/python3.11/site-packages/sqlalchemy/engine/base.py", line 1638, in _execute_clauseelement
    ret = self._execute_context(
          ^^^^^^^^^^^^^^^^^^^^^^
  File "/Users/GihadCoorey11/Desktop/CITS3403/Songversation/Songversation-venv/lib/python3.11/site-packages/sqlalchemy/engine/base.py", line 1842, in _execute_context
    return self._exec_single_context(
           ^^^^^^^^^^^^^^^^^^^^^^^^^^
  File "/Users/GihadCoorey11/Desktop/CITS3403/Songversation/Songversation-venv/lib/python3.11/site-packages/sqlalchemy/engine/base.py", line 1983, in _exec_single_context
    self._handle_dbapi_exception(
  File "/Users/GihadCoorey11/Desktop/CITS3403/Songversation/Songversation-venv/lib/python3.11/site-packages/sqlalchemy/engine/base.py", line 2326, in _handle_dbapi_exception
    raise sqlalchemy_exception.with_traceback(exc_info[2]) from e
  File "/Users/GihadCoorey11/Desktop/CITS3403/Songversation/Songversation-venv/lib/python3.11/site-packages/sqlalchemy/engine/base.py", line 1964, in _exec_single_context
    self.dialect.do_execute(
  File "/Users/GihadCoorey11/Desktop/CITS3403/Songversation/Songversation-venv/lib/python3.11/site-packages/sqlalchemy/engine/default.py", line 748, in do_execute
    cursor.execute(statement, parameters)
sqlalchemy.exc.OperationalError: (sqlite3.OperationalError) no such table: track_lyrics
[SQL: SELECT track_lyrics.id AS track_lyrics_id, track_lyrics.last_cache_date AS track_lyrics_last_cache_date, track_lyrics.lyric_count AS track_lyrics_lyric_count, track_lyrics.track_id AS track_lyrics_track_id 
FROM track_lyrics 
WHERE track_lyrics.track_id = ?
 LIMIT ? OFFSET ?]
[parameters: ('3ZP18us6p6LHOZMG1LLUjF', 1, 0)]
(Background on this error at: https://sqlalche.me/e/20/e3q8)
2023-05-08 21:18:43,780 INFO: Starting Songversation... [in /Users/GihadCoorey11/Desktop/CITS3403/Songversation/app/__init__.py:42]
2023-05-08 21:19:28,801 ERROR: Exception on /get-track-lyrics [GET] [in /Users/GihadCoorey11/Desktop/CITS3403/Songversation/Songversation-venv/lib/python3.11/site-packages/flask/app.py:1744]
Traceback (most recent call last):
  File "/Users/GihadCoorey11/Desktop/CITS3403/Songversation/Songversation-venv/lib/python3.11/site-packages/sqlalchemy/engine/base.py", line 1964, in _exec_single_context
    self.dialect.do_execute(
  File "/Users/GihadCoorey11/Desktop/CITS3403/Songversation/Songversation-venv/lib/python3.11/site-packages/sqlalchemy/engine/default.py", line 748, in do_execute
    cursor.execute(statement, parameters)
sqlite3.OperationalError: no such table: track_lyrics

The above exception was the direct cause of the following exception:

Traceback (most recent call last):
  File "/Users/GihadCoorey11/Desktop/CITS3403/Songversation/Songversation-venv/lib/python3.11/site-packages/flask/app.py", line 2528, in wsgi_app
    response = self.full_dispatch_request()
               ^^^^^^^^^^^^^^^^^^^^^^^^^^^^
  File "/Users/GihadCoorey11/Desktop/CITS3403/Songversation/Songversation-venv/lib/python3.11/site-packages/flask/app.py", line 1825, in full_dispatch_request
    rv = self.handle_user_exception(e)
         ^^^^^^^^^^^^^^^^^^^^^^^^^^^^^
  File "/Users/GihadCoorey11/Desktop/CITS3403/Songversation/Songversation-venv/lib/python3.11/site-packages/flask/app.py", line 1823, in full_dispatch_request
    rv = self.dispatch_request()
         ^^^^^^^^^^^^^^^^^^^^^^^
  File "/Users/GihadCoorey11/Desktop/CITS3403/Songversation/Songversation-venv/lib/python3.11/site-packages/flask/app.py", line 1799, in dispatch_request
    return self.ensure_sync(self.view_functions[rule.endpoint])(**view_args)
           ^^^^^^^^^^^^^^^^^^^^^^^^^^^^^^^^^^^^^^^^^^^^^^^^^^^^^^^^^^^^^^^^^
  File "/Users/GihadCoorey11/Desktop/CITS3403/Songversation/Songversation-venv/lib/python3.11/site-packages/asgiref/sync.py", line 240, in __call__
    return call_result.result()
           ^^^^^^^^^^^^^^^^^^^^
  File "/opt/homebrew/Cellar/python@3.11/3.11.3/Frameworks/Python.framework/Versions/3.11/lib/python3.11/concurrent/futures/_base.py", line 449, in result
    return self.__get_result()
           ^^^^^^^^^^^^^^^^^^^
  File "/opt/homebrew/Cellar/python@3.11/3.11.3/Frameworks/Python.framework/Versions/3.11/lib/python3.11/concurrent/futures/_base.py", line 401, in __get_result
    raise self._exception
  File "/Users/GihadCoorey11/Desktop/CITS3403/Songversation/Songversation-venv/lib/python3.11/site-packages/asgiref/sync.py", line 306, in main_wrap
    result = await self.awaitable(*args, **kwargs)
             ^^^^^^^^^^^^^^^^^^^^^^^^^^^^^^^^^^^^^
  File "/Users/GihadCoorey11/Desktop/CITS3403/Songversation/app/api/spotify_api.py", line 140, in get_track_lyrics
    lyric_cache = TrackLyrics.query.filter(TrackLyrics.track_id == track_id).first()
                  ^^^^^^^^^^^^^^^^^^^^^^^^^^^^^^^^^^^^^^^^^^^^^^^^^^^^^^^^^^^^^^^^^^
  File "/Users/GihadCoorey11/Desktop/CITS3403/Songversation/Songversation-venv/lib/python3.11/site-packages/sqlalchemy/orm/query.py", line 2752, in first
    return self.limit(1)._iter().first()  # type: ignore
           ^^^^^^^^^^^^^^^^^^^^^
  File "/Users/GihadCoorey11/Desktop/CITS3403/Songversation/Songversation-venv/lib/python3.11/site-packages/sqlalchemy/orm/query.py", line 2855, in _iter
    result: Union[ScalarResult[_T], Result[_T]] = self.session.execute(
                                                  ^^^^^^^^^^^^^^^^^^^^^
  File "/Users/GihadCoorey11/Desktop/CITS3403/Songversation/Songversation-venv/lib/python3.11/site-packages/sqlalchemy/orm/session.py", line 2229, in execute
    return self._execute_internal(
           ^^^^^^^^^^^^^^^^^^^^^^^
  File "/Users/GihadCoorey11/Desktop/CITS3403/Songversation/Songversation-venv/lib/python3.11/site-packages/sqlalchemy/orm/session.py", line 2124, in _execute_internal
    result: Result[Any] = compile_state_cls.orm_execute_statement(
                          ^^^^^^^^^^^^^^^^^^^^^^^^^^^^^^^^^^^^^^^^
  File "/Users/GihadCoorey11/Desktop/CITS3403/Songversation/Songversation-venv/lib/python3.11/site-packages/sqlalchemy/orm/context.py", line 253, in orm_execute_statement
    result = conn.execute(
             ^^^^^^^^^^^^^
  File "/Users/GihadCoorey11/Desktop/CITS3403/Songversation/Songversation-venv/lib/python3.11/site-packages/sqlalchemy/engine/base.py", line 1414, in execute
    return meth(
           ^^^^^
  File "/Users/GihadCoorey11/Desktop/CITS3403/Songversation/Songversation-venv/lib/python3.11/site-packages/sqlalchemy/sql/elements.py", line 486, in _execute_on_connection
    return connection._execute_clauseelement(
           ^^^^^^^^^^^^^^^^^^^^^^^^^^^^^^^^^^
  File "/Users/GihadCoorey11/Desktop/CITS3403/Songversation/Songversation-venv/lib/python3.11/site-packages/sqlalchemy/engine/base.py", line 1638, in _execute_clauseelement
    ret = self._execute_context(
          ^^^^^^^^^^^^^^^^^^^^^^
  File "/Users/GihadCoorey11/Desktop/CITS3403/Songversation/Songversation-venv/lib/python3.11/site-packages/sqlalchemy/engine/base.py", line 1842, in _execute_context
    return self._exec_single_context(
           ^^^^^^^^^^^^^^^^^^^^^^^^^^
  File "/Users/GihadCoorey11/Desktop/CITS3403/Songversation/Songversation-venv/lib/python3.11/site-packages/sqlalchemy/engine/base.py", line 1983, in _exec_single_context
    self._handle_dbapi_exception(
  File "/Users/GihadCoorey11/Desktop/CITS3403/Songversation/Songversation-venv/lib/python3.11/site-packages/sqlalchemy/engine/base.py", line 2326, in _handle_dbapi_exception
    raise sqlalchemy_exception.with_traceback(exc_info[2]) from e
  File "/Users/GihadCoorey11/Desktop/CITS3403/Songversation/Songversation-venv/lib/python3.11/site-packages/sqlalchemy/engine/base.py", line 1964, in _exec_single_context
    self.dialect.do_execute(
  File "/Users/GihadCoorey11/Desktop/CITS3403/Songversation/Songversation-venv/lib/python3.11/site-packages/sqlalchemy/engine/default.py", line 748, in do_execute
    cursor.execute(statement, parameters)
sqlalchemy.exc.OperationalError: (sqlite3.OperationalError) no such table: track_lyrics
[SQL: SELECT track_lyrics.id AS track_lyrics_id, track_lyrics.last_cache_date AS track_lyrics_last_cache_date, track_lyrics.lyric_count AS track_lyrics_lyric_count, track_lyrics.track_id AS track_lyrics_track_id 
FROM track_lyrics 
WHERE track_lyrics.track_id = ?
 LIMIT ? OFFSET ?]
[parameters: ('1JSTJqkT5qHq8MDJnJbRE1', 1, 0)]
(Background on this error at: https://sqlalche.me/e/20/e3q8)
