2023-05-09 10:39:11,185 INFO: Starting Songversation... [in /Users/GihadCoorey11/Desktop/CITS3403/Songversation/app/__init__.py:42]
2023-05-09 10:39:16,552 INFO: Starting Songversation... [in /Users/GihadCoorey11/Desktop/CITS3403/Songversation/app/__init__.py:42]
2023-05-09 10:39:32,243 ERROR: Exception on / [GET] [in /Users/GihadCoorey11/Desktop/CITS3403/Songversation/Songversation-venv/lib/python3.11/site-packages/flask/app.py:1744]
Traceback (most recent call last):
  File "/Users/GihadCoorey11/Desktop/CITS3403/Songversation/Songversation-venv/lib/python3.11/site-packages/spotipy/oauth2.py", line 588, in refresh_access_token
    response.raise_for_status()
  File "/Users/GihadCoorey11/Desktop/CITS3403/Songversation/Songversation-venv/lib/python3.11/site-packages/requests/models.py", line 1021, in raise_for_status
    raise HTTPError(http_error_msg, response=self)
requests.exceptions.HTTPError: 400 Client Error: Bad Request for url: https://accounts.spotify.com/api/token

During handling of the above exception, another exception occurred:

Traceback (most recent call last):
  File "/Users/GihadCoorey11/Desktop/CITS3403/Songversation/Songversation-venv/lib/python3.11/site-packages/flask/app.py", line 2528, in wsgi_app
    response = self.full_dispatch_request()
               ^^^^^^^^^^^^^^^^^^^^^^^^^^^^
  File "/Users/GihadCoorey11/Desktop/CITS3403/Songversation/Songversation-venv/lib/python3.11/site-packages/flask/app.py", line 1825, in full_dispatch_request
    rv = self.handle_user_exception(e)
         ^^^^^^^^^^^^^^^^^^^^^^^^^^^^^
  File "/Users/GihadCoorey11/Desktop/CITS3403/Songversation/Songversation-venv/lib/python3.11/site-packages/flask/app.py", line 1823, in full_dispatch_request
    rv = self.dispatch_request()
         ^^^^^^^^^^^^^^^^^^^^^^^
  File "/Users/GihadCoorey11/Desktop/CITS3403/Songversation/Songversation-venv/lib/python3.11/site-packages/flask/app.py", line 1799, in dispatch_request
    return self.ensure_sync(self.view_functions[rule.endpoint])(**view_args)
           ^^^^^^^^^^^^^^^^^^^^^^^^^^^^^^^^^^^^^^^^^^^^^^^^^^^^^^^^^^^^^^^^^
  File "/Users/GihadCoorey11/Desktop/CITS3403/Songversation/app/routes.py", line 18, in index
    return render_template('index.html', title='Home - Songversation', user_data=SpotifyWebUserData())
                                                                                 ^^^^^^^^^^^^^^^^^^^^
  File "/Users/GihadCoorey11/Desktop/CITS3403/Songversation/app/helpers/spotify_helper.py", line 80, in __init__
    sp = SpotifyHelper()
         ^^^^^^^^^^^^^^^
  File "/Users/GihadCoorey11/Desktop/CITS3403/Songversation/app/helpers/spotify_helper.py", line 19, in __init__
    session['token_info'], authorised = self.get_token()
                                        ^^^^^^^^^^^^^^^^
  File "/Users/GihadCoorey11/Desktop/CITS3403/Songversation/app/helpers/spotify_helper.py", line 51, in get_token
    token_info = sp_oauth.refresh_access_token(
                 ^^^^^^^^^^^^^^^^^^^^^^^^^^^^^^
  File "/Users/GihadCoorey11/Desktop/CITS3403/Songversation/Songversation-venv/lib/python3.11/site-packages/spotipy/oauth2.py", line 596, in refresh_access_token
    self._handle_oauth_error(http_error)
  File "/Users/GihadCoorey11/Desktop/CITS3403/Songversation/Songversation-venv/lib/python3.11/site-packages/spotipy/oauth2.py", line 146, in _handle_oauth_error
    raise SpotifyOauthError(
spotipy.oauth2.SpotifyOauthError: error: invalid_grant, error_description: Refresh token revoked
2023-05-09 10:56:19,852 INFO: Starting Songversation... [in /Users/GihadCoorey11/Desktop/CITS3403/Songversation/app/__init__.py:42]
2023-05-09 11:12:01,541 INFO: Starting Songversation... [in /Users/GihadCoorey11/Desktop/CITS3403/Songversation/app/__init__.py:42]
2023-05-09 11:13:58,606 INFO: Starting Songversation... [in /Users/GihadCoorey11/Desktop/CITS3403/Songversation/app/__init__.py:42]
2023-05-09 11:59:11,696 INFO: Starting Songversation... [in /Users/GihadCoorey11/Desktop/CITS3403/Songversation/app/__init__.py:42]
2023-05-09 11:59:16,024 INFO: Starting Songversation... [in /Users/GihadCoorey11/Desktop/CITS3403/Songversation/app/__init__.py:42]
2023-05-09 12:18:44,761 INFO: Starting Songversation... [in /Users/GihadCoorey11/Desktop/CITS3403/Songversation/app/__init__.py:42]
2023-05-09 12:18:48,077 INFO: Starting Songversation... [in /Users/GihadCoorey11/Desktop/CITS3403/Songversation/app/__init__.py:42]
2023-05-09 12:24:21,046 ERROR: Exception on / [GET] [in /Users/GihadCoorey11/Desktop/CITS3403/Songversation/Songversation-venv/lib/python3.11/site-packages/flask/app.py:1744]
Traceback (most recent call last):
  File "/Users/GihadCoorey11/Desktop/CITS3403/Songversation/Songversation-venv/lib/python3.11/site-packages/spotipy/oauth2.py", line 588, in refresh_access_token
    response.raise_for_status()
  File "/Users/GihadCoorey11/Desktop/CITS3403/Songversation/Songversation-venv/lib/python3.11/site-packages/requests/models.py", line 1021, in raise_for_status
    raise HTTPError(http_error_msg, response=self)
requests.exceptions.HTTPError: 400 Client Error: Bad Request for url: https://accounts.spotify.com/api/token

During handling of the above exception, another exception occurred:

Traceback (most recent call last):
  File "/Users/GihadCoorey11/Desktop/CITS3403/Songversation/Songversation-venv/lib/python3.11/site-packages/flask/app.py", line 2528, in wsgi_app
    response = self.full_dispatch_request()
               ^^^^^^^^^^^^^^^^^^^^^^^^^^^^
  File "/Users/GihadCoorey11/Desktop/CITS3403/Songversation/Songversation-venv/lib/python3.11/site-packages/flask/app.py", line 1825, in full_dispatch_request
    rv = self.handle_user_exception(e)
         ^^^^^^^^^^^^^^^^^^^^^^^^^^^^^
  File "/Users/GihadCoorey11/Desktop/CITS3403/Songversation/Songversation-venv/lib/python3.11/site-packages/flask/app.py", line 1823, in full_dispatch_request
    rv = self.dispatch_request()
         ^^^^^^^^^^^^^^^^^^^^^^^
  File "/Users/GihadCoorey11/Desktop/CITS3403/Songversation/Songversation-venv/lib/python3.11/site-packages/flask/app.py", line 1799, in dispatch_request
    return self.ensure_sync(self.view_functions[rule.endpoint])(**view_args)
           ^^^^^^^^^^^^^^^^^^^^^^^^^^^^^^^^^^^^^^^^^^^^^^^^^^^^^^^^^^^^^^^^^
  File "/Users/GihadCoorey11/Desktop/CITS3403/Songversation/app/routes.py", line 18, in index
    return render_template('index.html', title='Home - Songversation', user_data=SpotifyWebUserData())
                                                                                 ^^^^^^^^^^^^^^^^^^^^
  File "/Users/GihadCoorey11/Desktop/CITS3403/Songversation/app/helpers/spotify_helper.py", line 80, in __init__
    sp = SpotifyHelper()
         ^^^^^^^^^^^^^^^
  File "/Users/GihadCoorey11/Desktop/CITS3403/Songversation/app/helpers/spotify_helper.py", line 19, in __init__
    session['token_info'], authorised = self.get_token()
                                        ^^^^^^^^^^^^^^^^
  File "/Users/GihadCoorey11/Desktop/CITS3403/Songversation/app/helpers/spotify_helper.py", line 51, in get_token
    token_info = sp_oauth.refresh_access_token(
                 ^^^^^^^^^^^^^^^^^^^^^^^^^^^^^^
  File "/Users/GihadCoorey11/Desktop/CITS3403/Songversation/Songversation-venv/lib/python3.11/site-packages/spotipy/oauth2.py", line 596, in refresh_access_token
    self._handle_oauth_error(http_error)
  File "/Users/GihadCoorey11/Desktop/CITS3403/Songversation/Songversation-venv/lib/python3.11/site-packages/spotipy/oauth2.py", line 146, in _handle_oauth_error
    raise SpotifyOauthError(
spotipy.oauth2.SpotifyOauthError: error: invalid_grant, error_description: Refresh token revoked
